terminate called after throwing an instance of 'boost::wrapexcept<std::system_error>'
  what():  connect: Connection refused
/home/hdy/data/note/0-wen/0-batch/系统脚本/run-cpp：行 3: 1631140 已放弃               （核心已转储） ./a.out
