Traceback (most recent call last):
  File "a.py", line 1, in <module>
    import subprocess
  File "/home/hdy/data/gitHome/python/subprocess.py", line 18, in <module>
    Test().fun()
  File "/home/hdy/data/gitHome/python/subprocess.py", line 8, in fun
    ret = subprocess.run(['ls', '-l'], capture_output=True ,text=True )
AttributeError: partially initialized module 'subprocess' has no attribute 'run' (most likely due to a circular import)
Error in sys.excepthook:
Traceback (most recent call last):
  File "/usr/lib/python3/dist-packages/apport_python_hook.py", line 72, in apport_excepthook
    from apport.fileutils import likely_packaged, get_recent_crashes
  File "/usr/lib/python3/dist-packages/apport/__init__.py", line 5, in <module>
    from apport.report import Report
  File "/usr/lib/python3/dist-packages/apport/report.py", line 12, in <module>
    import subprocess, tempfile, os.path, re, pwd, grp, os, io
  File "/home/hdy/data/gitHome/python/subprocess.py", line 18, in <module>
    Test().fun()
  File "/home/hdy/data/gitHome/python/subprocess.py", line 8, in fun
    ret = subprocess.run(['ls', '-l'], capture_output=True ,text=True )
AttributeError: partially initialized module 'subprocess' has no attribute 'run' (most likely due to a circular import)

Original exception was:
Traceback (most recent call last):
  File "a.py", line 1, in <module>
    import subprocess
  File "/home/hdy/data/gitHome/python/subprocess.py", line 18, in <module>
    Test().fun()
  File "/home/hdy/data/gitHome/python/subprocess.py", line 8, in fun
    ret = subprocess.run(['ls', '-l'], capture_output=True ,text=True )
AttributeError: partially initialized module 'subprocess' has no attribute 'run' (most likely due to a circular import)
